<?xml version="1.0" ?>
<!-- =================================================================================== -->
<!-- |    This document was autogenerated by xacro from /home/ros/Desktop/catkin_ws/src/val_description/nn_model/robots/valkyrie_A.xacro | -->
<!-- |    EDITING THIS FILE BY HAND IS NOT RECOMMENDED                                 | -->
<!-- =================================================================================== -->
<robot name="Valkyrie" xmlns:xacro="http://ros.org/wiki/xacro">
  <!--Yaw-->
  <!--pitch-->
  <!--roll-->
  <!-- Pulley-1 diameter = 0.01707m -->
  <!-- Pulley-2 diameter = 0.0127m -->
  <!-- Pulley-3 diameter = 0.01016 -->
  <!-- Pulley-1 diameter = 0.01707m -->
  <!-- Pulley-2 diameter = 0.0127m -->
  <!-- Pulley-3 diameter = 0.01016 -->
  <!-- Pulley-1 diameter = 0.01707m -->
  <!-- Pulley-2 diameter = 0.0127m -->
  <!-- Pulley-3 diameter = 0.01016 -->
  <!-- Pulley-1 diameter = 0.01707m -->
  <!-- Pulley-2 diameter = 0.0127m -->
  <!-- Pulley-3 diameter = 0.01016 -->
  <!-- Pelvis include -->
  <!-- Leg include -->
  <!-- Head include -->
  <!-- Arm include -->
  <!-- Waist include -->


<!--	Orderd Joints -->

		<joint name="leftShoulderPitch" type="revolute">
    <origin rpy="0.0 0.0 0.0" xyz="-0.0316 0.0 0.2984"/>
    <axis xyz="0 1 0"/>
    <parent link="torso"/>
    <child link="leftShoulderPitchLink"/>
    <limit effort="190" lower="-2.85" upper="2.0" velocity="5.89"/>

    <dynamics damping="0.1" friction="0.0"/>
  </joint>


  <joint name="leftShoulderRoll" type="revolute">
    <origin rpy="0.0 0.0 0.0" xyz="0.0 0.2499 0.0"/>
    <axis xyz="1 0 0"/>
    <parent link="leftShoulderPitchLink"/>
    <child link="leftShoulderRollLink"/>
    <limit effort="190" lower="-1.519" upper="1.266" velocity="5.89"/>

    <dynamics damping="0.1" friction="0.0"/>
  </joint>
  <joint name="leftShoulderYaw" type="revolute">
    <origin rpy="0.0 0.0 0.0" xyz="0.0 0.0 0.0"/>
    <axis xyz="0 1 0"/>
    <parent link="leftShoulderRollLink"/>
    <child link="leftShoulderYawLink"/>
    <limit effort="65" lower="-3.1" upper="2.18" velocity="11.5"/>

    <dynamics damping="0.1" friction="0.0"/>
  </joint>

	  <joint name="leftElbowPitch" type="revolute">
    <origin rpy="0.0 0.0 0.0" xyz="0.0254 0.33 0.0"/>
    <axis xyz="0 0 1"/>
    <parent link="leftShoulderYawLink"/>
    <child link="leftElbowPitchLink"/>
    <limit effort="65" lower="-2.174" upper="0.12" velocity="11.5"/>

    <dynamics damping="0.1" friction="0.0"/>
  </joint>


	<joint name="leftForearmYaw" type="revolute">
    <origin rpy="0.0 0.0 0.0" xyz="-0.0254 0 0"/>
    <axis xyz="0 1 0"/>
    <parent link="leftElbowPitchLink"/>
    <child link="leftForearmLink"/>
    <limit effort="26" lower="-2.019" upper="3.14" velocity="5"/>

    <dynamics damping="0.1" friction="0.0"/>
  </joint>
  <joint name="leftWristRoll" type="revolute">
    <origin rpy="0.0 0.0 0.0" xyz="0.0 0.2871 0.0"/>
    <axis xyz="1 0 0"/>
    <parent link="leftForearmLink"/>
    <child link="leftWristRollLink"/>
    <limit effort="14" lower="-0.62" upper="0.625" velocity="1"/>

    <dynamics damping="0.1" friction="0.0"/>
  </joint>
  <joint name="leftWristPitch" type="revolute">
    <origin rpy="0.0 0.0 0.0" xyz="0.0 0.0 0.0"/>
    <axis xyz="0 0 1"/>
    <parent link="leftWristRollLink"/>
    <child link="leftPalm"/>
    <limit effort="14" lower="-0.36" upper="0.49" velocity="1"/>

    <dynamics damping="0.1" friction="0.0"/>
  </joint>






<joint name="torsoYaw" type="fixed">
    <origin rpy="0.0 0.0 0.0" xyz="0.0 0.0 0.0"/>
    <axis xyz="0 0 1"/>
    <parent link="pelvis"/>
    <child link="torsoYawLink"/>
    <limit effort="190" lower="-1.329" upper="1.181" velocity="5.89"/>

    <dynamics damping="0.1" friction="0.0"/>
  </joint>


	<joint name="torsoPitch" type="fixed">
    <origin rpy="0.0 0.0 0.0" xyz="0.04191 0.0 0.0"/>
    <axis xyz="0 1 0"/>
    <parent link="torsoYawLink"/>
    <child link="torsoPitchLink"/>
    <limit effort="150" lower="-0.13" upper="0.666" velocity="9"/>

    <dynamics damping="0.1" friction="0.0"/>
  </joint>

	<joint name="torsoRoll" type="fixed">
    <origin rpy="0.0 0.0 0.0" xyz="0.0 0.0 0.0203"/>
    <axis xyz="1 0 0"/>
    <parent link="torsoPitchLink"/>
    <child link="torso"/>
    <limit effort="150" lower="-0.23" upper="0.255" velocity="9"/>

    <dynamics damping="0.1" friction="0.0"/>
  </joint>






  <link name="pelvis">
    <inertial>
      <mass value="8.22"/>
      <origin rpy="0 0 0" xyz="-0.00532 -0.003512 -0.0036"/>
      <inertia ixx="0.11866378" ixy="-0.000143482" ixz="0.003271293" iyy="0.097963425" iyz="0.002159545" izz="0.083854638"/>
    </inertial>
    <visual>
      <geometry>
        <mesh filename="meshes2/pelvis/pelvis.dae"/>
      </geometry>
      <origin rpy="0.0 0.0 0.0" xyz="0.0 0.0 0.0"/>
    </visual>
    <collision>
      <geometry>
        <mesh filename="meshes2/pelvis/pelvis.dae"/>
      </geometry>
      <origin rpy="0 0 0" xyz="0 0 0"/>
    </collision>
  </link>
  <link name="torsoYawLink">
    <inertial>
      <mass value="0.5"/>
      <origin rpy="0 0 0" xyz="0.000000 0.000000 -0.010000"/>
      <inertia ixx="0.000608427" ixy="-1.172e-06" ixz="1.647e-06" iyy="0.000620328" iyz="-2.33e-07" izz="0.001078108"/>
    </inertial>
    <visual>
      <geometry>
        <mesh filename="meshes2/torso/torsoyaw.dae"/>
      </geometry>
      <origin rpy="0.0 0.0 0.0" xyz="0.0 0.0 0.0"/>
    </visual>
    <collision>
      <geometry>
        <mesh filename="meshes2/torso/torsoyaw.dae"/>
      </geometry>
      <origin rpy="0 0 0" xyz="0 0 0"/>
    </collision>
  </link>
  <link name="torsoPitchLink">
    <inertial>
      <mass value="0.1"/>
      <origin rpy="0 0 0" xyz="0.000000 0.000000  0.005000"/>
      <inertia ixx="3.032e-05" ixy="0.0" ixz="-1.145e-06" iyy="2.1274e-05" iyz="0.0" izz="2.8285e-05"/>
    </inertial>
    <visual>
      <geometry>
        <mesh filename="meshes2/torso/torsopitch.dae"/>
      </geometry>
      <origin rpy="0.0 0.0 0.0" xyz="0.0 0.0 0.0"/>
    </visual>
    <collision>
      <geometry>
        <mesh filename="meshes2/torso/torsopitch.dae"/>
      </geometry>
      <origin rpy="0 0 0" xyz="0 0 0"/>
    </collision>
  </link>
  <link name="torso">
    <inertial>
      <mass value="39.47"/>
      <origin rpy="0 0 0" xyz="-0.095548 -0.003337 0.243098"/>
      <inertia ixx="0.87326933" ixy="9.9563e-05" ixz="0.061345211" iyy="1.0108485" iyz="0.00181849" izz="0.77839801"/>
    </inertial>
    <visual>
      <geometry>
        <mesh filename="meshes2/torso/torso.dae"/>
      </geometry>
      <origin rpy="0.0 0.0 0.0" xyz="0.0 0.0 0.0"/>
    </visual>
    <collision>
      <geometry>
        <mesh filename="meshes2/torso/torso.dae"/>
      </geometry>
      <origin rpy="0 0 0" xyz="0 0 0"/>
    </collision>
  </link>





  <link name="lowerNeckPitchLink">
    <inertial>
      <mass value="1.05"/>
      <origin rpy="0 0 0" xyz="-0.020000 0.000000  0.040000"/>
      <inertia ixx="0.001470716" ixy="-0.000126021" ixz="0.000632521" iyy="0.001851919" iyz="0.000243012" izz="0.000832117"/>
    </inertial>
    <visual>
      <geometry>
        <mesh filename="meshes2/head/neckj1.dae"/>
      </geometry>
      <origin rpy="0.0 0.0 0.0" xyz="0.0 0.0 0.0"/>
    </visual>
    <collision>
      <geometry>
        <mesh filename="meshes2/head/neckj1.dae"/>
      </geometry>
      <origin rpy="0 0 0" xyz="0 0 0"/>
    </collision>
  </link>
  <link name="neckYawLink">
    <inertial>
      <mass value="1.4"/>
      <origin rpy="0 0 0" xyz="-0.030000  -0.010000 0.150000"/>
      <inertia ixx="0.001997698" ixy="-0.000180062" ixz="0.000723677" iyy="0.002919928" iyz="0.000246467" izz="0.002119751"/>
    </inertial>
    <visual>
      <geometry>
        <mesh filename="meshes2/head/neckj2.dae"/>
      </geometry>
      <origin rpy="0.0 0.0 0.0" xyz="0.0 0.0 0.0"/>
    </visual>
    <collision>
      <geometry>
        <mesh filename="meshes2/head/neckj2.dae"/>
      </geometry>
      <origin rpy="0 0 0" xyz="0 0 0"/>
    </collision>
  </link>
  <link name="upperNeckPitchLink">
    <inertial>
      <mass value="3.89"/>
      <origin rpy="0 0 0" xyz="0.100912 0.005783 0.034787"/>
      <inertia ixx="0.039847525" ixy="-0.000470418" ixz="-0.002829842" iyy="0.041418564" iyz="-0.000782564" izz="0.036841236"/>
    </inertial>
    <visual>
      <geometry>
        <mesh filename="meshes2/head/head_multisense_no_visor.dae"/>
      </geometry>
      <origin rpy="0.0 0.0 0.0" xyz="0.0 0.0 0.0"/>
    </visual>
    <collision>
      <geometry>
        <mesh filename="meshes2/head/head_multisense_no_visor.dae"/>
      </geometry>
      <origin rpy="0 0 0" xyz="0 0 0"/>
    </collision>
  </link>
  <joint name="lowerNeckPitch" type="fixed">
    <origin rpy="0.0 0.0 0.0" xyz="0.0203518 0.0 0.33845"/>
    <axis xyz="0 1 0"/>
    <parent link="torso"/>
    <child link="lowerNeckPitchLink"/>
    <limit effort="26" lower="0" upper="1.162" velocity="5"/>

    <dynamics damping="0.1" friction="0.0"/>
  </joint>
  <joint name="neckYaw" type="fixed">
    <origin rpy="0.0 0.0 0.0" xyz="-0.051924 0.0 0.0"/>
    <axis xyz="0 0 1"/>
    <parent link="lowerNeckPitchLink"/>
    <child link="neckYawLink"/>
    <limit effort="26" lower="-1.04719755" upper="1.04719755" velocity="5"/>
    <dynamics damping="0.1" friction="0.0"/>
  </joint>
  <joint name="upperNeckPitch" type="fixed">
    <origin rpy="0.0 0.0 0.0" xyz="-0.06 0 0.195997"/>
    <axis xyz="0 1 0"/>
    <parent link="neckYawLink"/>
    <child link="upperNeckPitchLink"/>
    <limit effort="26" lower="-0.872" upper="0.0" velocity="5"/>
    <dynamics damping="0.1" friction="0.0"/>
  </joint>
  <link name="rightShoulderPitchLink">
    <inertial>
      <mass value="2.65"/>
      <origin rpy="0 0 0" xyz="0.012 -0.251 0.000000"/>
      <inertia ixx="0.013718167" ixy="0.0" ixz="0.0" iyy="0.010502833" iyz="0.0" izz="0.014806433"/>
    </inertial>
    <visual>
      <geometry>
        <mesh filename="meshes2/arms/aj1_right.dae"/>
      </geometry>
      <origin rpy="0.0 0.0 0.0" xyz="0.0 0.0 0.0"/>
    </visual>
    <collision>
      <geometry>
        <mesh filename="meshes2/arms/aj1_right.dae"/>
      </geometry>
      <origin rpy="0 0 0" xyz="0 0 0"/>
    </collision>
  </link>
  <link name="rightShoulderRollLink">
    <inertial>
      <mass value="3.97"/>
      <origin rpy="0 0 0" xyz="0.008513 -0.02068 -0.001088"/>
      <inertia ixx="0.014598842" ixy="-0.00066764" ixz="3.629e-05" iyy="0.006452136" iyz="8.283e-05" izz="0.016848319"/>
    </inertial>
    <visual>
      <geometry>
        <mesh filename="meshes2/arms/aj2_right.dae"/>
      </geometry>
      <origin rpy="0.0 0.0 0.0" xyz="0.0 0.0 0.0"/>
    </visual>
    <collision>
      <geometry>
        <mesh filename="meshes2/arms/aj2_right.dae"/>
      </geometry>
      <origin rpy="0 0 0" xyz="0 0 0"/>
    </collision>
  </link>
  <link name="rightShoulderYawLink">
    <inertial>
      <mass value="3.085"/>
      <origin rpy="0 0 0" xyz="-0.004304 -0.209832 -0.007295"/>
      <inertia ixx="0.039355177" ixy="0.007827077" ixz="0.000753947" iyy="0.004905765" iyz="-0.002723873" izz="0.041879481"/>
    </inertial>
    <visual>
      <geometry>
        <mesh filename="meshes2/arms/aj3_right.dae"/>
      </geometry>
      <origin rpy="0.0 0.0 0.0" xyz="0.0 0.0 0.0"/>
    </visual>
    <collision>
      <geometry>
        <mesh filename="meshes2/arms/aj3_right.dae"/>
      </geometry>
      <origin rpy="0 0 0" xyz="0 0 0"/>
    </collision>
  </link>
  <link name="rightElbowPitchLink">
    <inertial>
      <mass value="1.83"/>
      <origin rpy="0 0 0" xyz="-0.020344 -0.014722 -0.0223"/>
      <inertia ixx="0.003314516" ixy="-0.000535099" ixz="-0.000728077" iyy="0.003505669" iyz="-0.000423865" izz="0.003011283"/>
    </inertial>
    <visual>
      <geometry>
        <mesh filename="meshes2/arms/aj4_right.dae"/>
      </geometry>
      <origin rpy="0.0 0.0 0.0" xyz="0.0 0.0 0.0"/>
    </visual>
    <collision>
      <geometry>
        <mesh filename="meshes2/arms/aj4_right.dae"/>
      </geometry>
      <origin rpy="0 0 0" xyz="0 0 0"/>
    </collision>
  </link>
  <joint name="rightShoulderPitch" type="fixed">
    <origin rpy="0.0 0.0 0.0" xyz="-0.0316 0.0 0.2984"/>
    <axis xyz="0 1 0"/>
    <parent link="torso"/>
    <child link="rightShoulderPitchLink"/>
    <limit effort="190" lower="-2.85" upper="2.0" velocity="5.89"/>

    <dynamics damping="0.1" friction="0.0"/>
  </joint>
  <joint name="rightShoulderRoll" type="fixed">
    <origin rpy="0.0 0.0 0.0" xyz="0.0 -0.2499 0.0"/>
    <axis xyz="1 0 0"/>
    <parent link="rightShoulderPitchLink"/>
    <child link="rightShoulderRollLink"/>
    <limit effort="190" lower="-1.266" upper="1.519" velocity="5.89"/>

    <dynamics damping="0.1" friction="0.0"/>
  </joint>
  <joint name="rightShoulderYaw" type="fixed">
    <origin rpy="0.0 0.0 0.0" xyz="0.0 0.0 0.0"/>
    <axis xyz="0 1 0"/>
    <parent link="rightShoulderRollLink"/>
    <child link="rightShoulderYawLink"/>
    <limit effort="65" lower="-3.1" upper="2.18" velocity="11.5"/>

    <dynamics damping="0.1" friction="0.0"/>
  </joint>
  <joint name="rightElbowPitch" type="fixed">
    <origin rpy="0.0 0.0 0.0" xyz="0.0254 -0.33 0.0"/>
    <axis xyz="0 0 1"/>
    <parent link="rightShoulderYawLink"/>
    <child link="rightElbowPitchLink"/>
    <limit effort="65" lower="-0.12" upper="2.174" velocity="11.5"/>

    <dynamics damping="0.1" friction="0.0"/>
  </joint>
  <link name="rightForearmLink">
    <inertial>
      <mass value="2.476"/>
      <origin rpy="0 0 0" xyz="0.015000 -0.13 0.019564"/>
      <inertia ixx="0.01175543" ixy="-0.001300853" ixz="-0.000727141" iyy="0.005071567" iyz="-0.001695416" izz="0.011365657"/>
    </inertial>
    <visual>
      <geometry>
        <mesh filename="meshes2/arms/aj5_right.dae"/>
      </geometry>
      <origin rpy="0.0 0.0 0.0" xyz="0.0 0.0 0.0"/>
    </visual>
    <collision>
      <geometry>
        <mesh filename="meshes2/arms/aj5_right.dae"/>
      </geometry>
      <origin rpy="0 0 0" xyz="0 0 0"/>
    </collision>
  </link>
  <link name="rightWristRollLink">
    <inertial>
      <mass value="0.14"/>
      <origin rpy="0 0 0" xyz="0 -0.0 0"/>
      <inertia ixx="3.0251e-05" ixy="-1.25e-07" ixz="-3.6e-08" iyy="3.772e-05" iyz="0.0" izz="9.395e-06"/>
    </inertial>
    <visual>
      <geometry>
        <mesh filename="meshes2/arms/aj6_right.dae"/>
      </geometry>
      <origin rpy="0.0 0.0 0.0" xyz="0.0 0.0 0.0"/>
    </visual>
    <collision>
      <geometry>
        <mesh filename="meshes2/arms/aj6_right.dae"/>
      </geometry>
      <origin rpy="0 0 0" xyz="0 0 0"/>
    </collision>
  </link>
  <link name="rightPalm">
    <inertial>
      <mass value="0.712"/>
      <origin rpy="0 0 0" xyz="0.002954 -0.052034 -0.000236"/>
      <inertia ixx="0.000943493" ixy="3.4393e-05" ixz="-3.8828e-05" iyy="0.000711024" iyz="2.3429e-05" izz="0.000610199"/>
    </inertial>
    <visual>
      <geometry>
        <mesh filename="meshes2/arms/palm_right.dae"/>
      </geometry>
      <origin rpy="0.0 0.0 0.0" xyz="0.0 0.0 0.0"/>
    </visual>
    <collision>
      <geometry>
        <mesh filename="meshes2/arms/palm_right.dae"/>
      </geometry>
      <origin rpy="0 0 0" xyz="0 0 0"/>
    </collision>
  </link>
  <joint name="rightForearmYaw" type="fixed">
    <origin rpy="0.0 0.0 0.0" xyz="-0.0254 0 0"/>
    <axis xyz="0 1 0"/>
    <parent link="rightElbowPitchLink"/>
    <child link="rightForearmLink"/>
    <limit effort="26" lower="-2.019" upper="3.14" velocity="5"/>

    <dynamics damping="0.1" friction="0.0"/>
  </joint>
  <joint name="rightWristRoll" type="fixed">
    <origin rpy="0.0 0.0 0.0" xyz="0.0 -0.2871 0.0"/>
    <axis xyz="1 0 0"/>
    <parent link="rightForearmLink"/>
    <child link="rightWristRollLink"/>
    <limit effort="14" lower="-0.625" upper="0.62" velocity="1"/>

    <dynamics damping="0.1" friction="0.0"/>
  </joint>
  <joint name="rightWristPitch" type="fixed">
    <origin rpy="0.0 0.0 0.0" xyz="0.0 0.0 0.0"/>
    <axis xyz="0 0 1"/>
    <parent link="rightWristRollLink"/>
    <child link="rightPalm"/>
    <limit effort="14" lower="-0.49" upper="0.36" velocity="1"/>

    <dynamics damping="0.1" friction="0.0"/>
  </joint>
  <link name="rightThumbRollLink">
    <inertial>
      <mass value="0.017"/>
      <origin rpy="0 0 0" xyz="0 -0.0 0.01"/>
      <inertia ixx="2.7778767e-06" ixy="5.6718533e-09" ixz="-9.5523207e-08" iyy="3.5462642e-06" iyz="3.663718e-08" izz="1.3553297e-06"/>
    </inertial>
    <visual>
      <geometry>
        <mesh filename="meshes2/fingers/thumbj1_right.dae"/>
      </geometry>
      <origin rpy="0.0 0.0 0.0" xyz="0.0 0.0 0.0"/>
    </visual>
    <collision>
      <geometry>
        <mesh filename="meshes2/fingers/thumbj1_right.dae"/>
      </geometry>
      <origin rpy="0 0 0" xyz="0 0 0"/>
    </collision>
  </link>
  <link name="rightThumbPitch1Link">
    <inertial>
      <mass value="0.02"/>
      <origin rpy="0 0 0" xyz="0.0 -0.005 0.02"/>
      <inertia ixx="4.239e-06" ixy="0.0" ixz="-0.0" iyy="4.582e-06" iyz="0.0" izz="1.47e-06"/>
    </inertial>
    <visual>
      <geometry>
        <mesh filename="meshes2/fingers/thumbj2_right.dae"/>
      </geometry>
      <origin rpy="0.0 0.0 0.0" xyz="0.0 0.0 0.0"/>
    </visual>
    <collision>
      <geometry>
        <mesh filename="meshes2/fingers/thumbj2_right.dae"/>
      </geometry>
      <origin rpy="0 0 0" xyz="0 0 0"/>
    </collision>
  </link>
  <link name="rightThumbPitch2Link">
    <inertial>
      <mass value="0.013"/>
      <origin rpy="0 0 0" xyz="0 -0.004 0.017"/>
      <inertia ixx="1.266e-06" ixy="0.0" ixz="-0.0" iyy="1.503e-06" iyz="-0.0" izz="6.99e-07"/>
    </inertial>
    <visual>
      <geometry>
        <mesh filename="meshes2/fingers/thumbj3_right.dae"/>
      </geometry>
      <origin rpy="0.0 0.0 0.0" xyz="0.0 0.0 0.0"/>
    </visual>
    <collision>
      <geometry>
        <mesh filename="meshes2/fingers/thumbj3_right.dae"/>
      </geometry>
      <origin rpy="0 0 0" xyz="0 0 0"/>
    </collision>
  </link>
  <link name="rightThumbPitch3Link">
    <inertial>
      <mass value="0.006"/>
      <origin rpy="0 0 0" xyz="0 -0.004 0.01"/>
      <inertia ixx="3.22e-07" ixy="0.0" ixz="0.0" iyy="4.06e-07" iyz="0.0" izz="2.1e-07"/>
    </inertial>
    <visual>
      <geometry>
        <mesh filename="meshes2/fingers/thumbj4_right.dae"/>
      </geometry>
      <origin rpy="0.0 0.0 0.0" xyz="0.0 0.0 0.0"/>
    </visual>
    <collision>
      <geometry>
        <mesh filename="meshes2/fingers/thumbj4_right.dae"/>
      </geometry>
      <origin rpy="0 0 0" xyz="0 0 0"/>
    </collision>
  </link>
  <joint name="rightThumbRoll" type="fixed">
    <origin rpy="0.3491 0.0 0.0" xyz="0.0049 -0.0351 0.0228"/>
    <axis xyz="0 1 0"/>
    <parent link="rightPalm"/>
    <child link="rightThumbRollLink"/>
    <limit effort="10" lower="0.0" upper="2.356" velocity="1"/>
    <dynamics damping="0.5" friction="0.5"/>
  </joint>
  <joint name="rightThumbPitch1" type="fixed">
    <origin rpy="-0.3491 0.0 0.0" xyz="0.0 0.0 0.0229"/>
    <axis xyz="1 0 0"/>
    <parent link="rightThumbRollLink"/>
    <child link="rightThumbPitch1Link"/>
    <limit effort="10" lower="0.0" upper="1.658" velocity="1"/>
    <dynamics damping="0.5" friction="0.5"/>
  </joint>
  <joint name="rightThumbPitch2" type="fixed">
    <origin rpy="0.0 0.0 0.0" xyz="0.0 -0.0066 0.0375"/>
    <axis xyz="1 0 0"/>
    <parent link="rightThumbPitch1Link"/>
    <child link="rightThumbPitch2Link"/>
    <limit effort="10" lower="0.0" upper="1.92" velocity="1"/>
    <dynamics damping="0.5" friction="0.5"/>
  </joint>
  <joint name="rightThumbPitch3" type="fixed">
    <origin rpy="0.0 0.0 0.0" xyz="0.0 -0.0049 0.0275"/>
    <axis xyz="1 0 0"/>
    <parent link="rightThumbPitch2Link"/>
    <child link="rightThumbPitch3Link"/>
    <limit effort="10" lower="0.0" upper="1.57" velocity="1"/>
    <dynamics damping="0.5" friction="0.5"/>
  </joint>
  <link name="rightIndexFingerPitch1Link">
    <inertial>
      <mass value="0.02"/>
      <origin rpy="0 0 0" xyz="0 -0.02 0"/>
      <inertia ixx="4.232e-06" ixy="-6e-08" ixz="-8e-09" iyy="1.215e-06" iyz="-7e-09" izz="3.892e-06"/>
    </inertial>
    <visual>
      <geometry>
        <mesh filename="meshes2/fingers/indexj1_right.dae"/>
      </geometry>
      <origin rpy="0.0 0.0 0.0" xyz="0.0 0.0 0.0"/>
    </visual>
    <collision>
      <geometry>
        <mesh filename="meshes2/fingers/indexj1_right.dae"/>
      </geometry>
      <origin rpy="0 0 0" xyz="0 0 0"/>
    </collision>
  </link>
  <link name="rightIndexFingerPitch2Link">
    <inertial>
      <mass value="0.018"/>
      <origin rpy="0 0 0" xyz="0 -0.013 0"/>
      <inertia ixx="1.562e-06" ixy="-1.7e-08" ixz="-1.3e-08" iyy="7.22e-07" iyz="3.1e-08" izz="1.255e-06"/>
    </inertial>
    <visual>
      <geometry>
        <mesh filename="meshes2/fingers/indexj2_right.dae"/>
      </geometry>
      <origin rpy="0.0 0.0 0.0" xyz="0.0 0.0 0.0"/>
    </visual>
    <collision>
      <geometry>
        <mesh filename="meshes2/fingers/indexj2_right.dae"/>
      </geometry>
      <origin rpy="0 0 0" xyz="0 0 0"/>
    </collision>
  </link>
  <link name="rightIndexFingerPitch3Link">
    <inertial>
      <mass value="0.01"/>
      <origin rpy="0 0 0" xyz="0 -0.01 0"/>
      <inertia ixx="6.02e-07" ixy="-2.4e-08" ixz="0.0" iyy="2.09e-07" iyz="1.7e-08" izz="5.02e-07"/>
    </inertial>
    <visual>
      <geometry>
        <mesh filename="meshes2/fingers/indexj3_right.dae"/>
      </geometry>
      <origin rpy="0.0 0.0 0.0" xyz="0.0 0.0 0.0"/>
    </visual>
    <collision>
      <geometry>
        <mesh filename="meshes2/fingers/indexj3_right.dae"/>
      </geometry>
      <origin rpy="0 0 0" xyz="0 0 0"/>
    </collision>
  </link>
  <joint name="rightIndexFingerPitch1" type="fixed">
    <origin rpy="-0.1745 0.0 0.0" xyz="0.0022 -0.0976 0.0235"/>
    <axis xyz="0 0 1"/>
    <parent link="rightPalm"/>
    <child link="rightIndexFingerPitch1Link"/>
    <limit effort="10" lower="0.0" upper="1.57" velocity="1"/>
    <dynamics damping="0.5" friction="0.5"/>
  </joint>
  <joint name="rightIndexFingerPitch2" type="fixed">
    <origin rpy="0.0 0.0 0.0" xyz="0.0 -0.0381 0.0"/>
    <axis xyz="0 0 1"/>
    <parent link="rightIndexFingerPitch1Link"/>
    <child link="rightIndexFingerPitch2Link"/>
    <limit effort="10" lower="0.0" upper="1.658" velocity="1"/>
    <dynamics damping="0.5" friction="0.5"/>
  </joint>
  <joint name="rightIndexFingerPitch3" type="fixed">
    <origin rpy="0.0 0.0 0.0" xyz="0.0 -0.0229 0"/>
    <axis xyz="0 0 1"/>
    <parent link="rightIndexFingerPitch2Link"/>
    <child link="rightIndexFingerPitch3Link"/>
    <limit effort="10" lower="0.0" upper="1.92" velocity="1"/>
    <dynamics damping="0.5" friction="0.5"/>
  </joint>
  <link name="rightMiddleFingerPitch1Link">
    <inertial>
      <mass value="0.02"/>
      <origin rpy="0 0 0" xyz="0 -0.02 0"/>
      <inertia ixx="5.148e-06" ixy="-4.2e-08" ixz="-1.1e-08" iyy="1.322e-06" iyz="-4e-09" izz="4.592e-06"/>
    </inertial>
    <visual>
      <geometry>
        <mesh filename="meshes2/fingers/middlej1_right.dae"/>
      </geometry>
      <origin rpy="0.0 0.0 0.0" xyz="0.0 0.0 0.0"/>
    </visual>
    <collision>
      <geometry>
        <mesh filename="meshes2/fingers/middlej1_right.dae"/>
      </geometry>
      <origin rpy="0 0 0" xyz="0 0 0"/>
    </collision>
  </link>
  <gazebo reference="rightMiddleFingerPitch1Link">
    <kp>1e5</kp>
    <kd>1</kd>
    <maxVel>0.1</maxVel>
    <minDepth>0.0015</minDepth>
  </gazebo>
  <link name="rightMiddleFingerPitch2Link">
    <inertial>
      <mass value="0.011"/>
      <origin rpy="0 0 0" xyz="0 -0.013 0"/>
      <inertia ixx="1.97e-06" ixy="3.4e-08" ixz="-1.1e-08" iyy="5.54e-07" iyz="-7.8e-08" izz="2.272e-06"/>
    </inertial>
    <visual>
      <geometry>
        <mesh filename="meshes2/fingers/middlej2_right.dae"/>
      </geometry>
      <origin rpy="0.0 0.0 0.0" xyz="0.0 0.0 0.0"/>
    </visual>
    <collision>
      <geometry>
        <mesh filename="meshes2/fingers/middlej2_right.dae"/>
      </geometry>
      <origin rpy="0 0 0" xyz="0 0 0"/>
    </collision>
  </link>
  <link name="rightMiddleFingerPitch3Link">
    <inertial>
      <mass value="0.006"/>
      <origin rpy="0 0 0" xyz="0 -0.01 0"/>
      <inertia ixx="3.96e-07" ixy="-9e-09" ixz="-1e-09" iyy="1.6e-07" iyz="1.6e-08" izz="3.03e-07"/>
    </inertial>
    <visual>
      <geometry>
        <mesh filename="meshes2/fingers/middlej3_right.dae"/>
      </geometry>
      <origin rpy="0.0 0.0 0.0" xyz="0.0 0.0 0.0"/>
    </visual>
    <collision>
      <geometry>
        <mesh filename="meshes2/fingers/middlej3_right.dae"/>
      </geometry>
      <origin rpy="0 0 0" xyz="0 0 0"/>
    </collision>
  </link>
  <joint name="rightMiddleFingerPitch1" type="fixed">
    <origin rpy="0.1222 0.0 0.0" xyz="0.0022 -0.097 -0.0119"/>
    <axis xyz="0 0 1"/>
    <parent link="rightPalm"/>
    <child link="rightMiddleFingerPitch1Link"/>
    <limit effort="10" lower="0.0" upper="1.658" velocity="1"/>
    <dynamics damping="0.5" friction="0.5"/>
  </joint>
  <joint name="rightMiddleFingerPitch2" type="fixed">
    <origin rpy="0.0 0.0 0.0" xyz="0.0 -0.0381 0.0"/>
    <axis xyz="0 0 1"/>
    <parent link="rightMiddleFingerPitch1Link"/>
    <child link="rightMiddleFingerPitch2Link"/>
    <limit effort="10" lower="0.0" upper="1.92" velocity="1"/>
    <dynamics damping="0.5" friction="0.5"/>
  </joint>
  <gazebo reference="rightMiddleFingerPitch2">
    <provideFeedback>1</provideFeedback>
    <implicitSpringDamper>1</implicitSpringDamper>
  </gazebo>
  <joint name="rightMiddleFingerPitch3" type="fixed">
    <origin rpy="0.0 0.0 0.0" xyz="0.0 -0.0229 0.0"/>
    <axis xyz="0 0 1"/>
    <parent link="rightMiddleFingerPitch2Link"/>
    <child link="rightMiddleFingerPitch3Link"/>
    <limit effort="10" lower="0.0" upper="1.57" velocity="1"/>
    <dynamics damping="0.5" friction="0.5"/>
  </joint>
  <link name="rightPinkyPitch1Link">
    <inertial>
      <mass value="0.02"/>
      <origin rpy="0 0 0" xyz="0 -0.02 0"/>
      <inertia ixx="5.148e-06" ixy="-4.2e-08" ixz="-1.1e-08" iyy="1.322e-06" iyz="-4e-09" izz="4.592e-06"/>
    </inertial>
    <visual>
      <geometry>
        <mesh filename="meshes2/fingers/pinkyj1_right.dae"/>
      </geometry>
      <origin rpy="0.0 0.0 0.0" xyz="0.0 0.0 0.0"/>
    </visual>
    <collision>
      <geometry>
        <mesh filename="meshes2/fingers/pinkyj1_right.dae"/>
      </geometry>
      <origin rpy="0 0 0" xyz="0 0 0"/>
    </collision>
  </link>

  <link name="rightPinkyPitch2Link">
    <inertial>
      <mass value="0.011"/>
      <origin rpy="0 0 0" xyz="0 -0.013 0"/>
      <inertia ixx="1.97e-06" ixy="3.4e-08" ixz="-1.1e-08" iyy="5.54e-07" iyz="-7.8e-08" izz="2.272e-06"/>
    </inertial>
    <visual>
      <geometry>
        <mesh filename="meshes2/fingers/pinkyj2_right.dae"/>
      </geometry>
      <origin rpy="0.0 0.0 0.0" xyz="0.0 0.0 0.0"/>
    </visual>
    <collision>
      <geometry>
        <mesh filename="meshes2/fingers/pinkyj2_right.dae"/>
      </geometry>
      <origin rpy="0 0 0" xyz="0 0 0"/>
    </collision>
  </link>
  <link name="rightPinkyPitch3Link">
    <inertial>
      <mass value="0.006"/>
      <origin rpy="0 0 0" xyz="0 -0.01 0"/>
      <inertia ixx="3.96e-07" ixy="-9e-09" ixz="-1e-09" iyy="1.6e-07" iyz="1.6e-08" izz="3.03e-07"/>
    </inertial>
    <visual>
      <geometry>
        <mesh filename="meshes2/fingers/pinkyj3_right.dae"/>
      </geometry>
      <origin rpy="0.0 0.0 0.0" xyz="0.0 0.0 0.0"/>
    </visual>
    <collision>
      <geometry>
        <mesh filename="meshes2/fingers/pinkyj3_right.dae"/>
      </geometry>
      <origin rpy="0 0 0" xyz="0 0 0"/>
    </collision>
  </link>
  <joint name="rightPinkyPitch1" type="fixed">
    <origin rpy="0.1222 0.0 0.0" xyz="0.0022 -0.0838 -0.041"/>
    <axis xyz="0 0 1"/>
    <parent link="rightPalm"/>
    <child link="rightPinkyPitch1Link"/>
    <limit effort="10" lower="0.0" upper="1.57" velocity="1"/>
    <dynamics damping="0.5" friction="0.5"/>
  </joint>

  <joint name="rightPinkyPitch2" type="fixed">
    <origin rpy="0.0 0.0 0.0" xyz="0.0 -0.0381 0.0"/>
    <axis xyz="0 0 1"/>
    <parent link="rightPinkyPitch1Link"/>
    <child link="rightPinkyPitch2Link"/>
    <limit effort="10" lower="0.0" upper="1.658" velocity="1"/>
    <dynamics damping="0.5" friction="0.5"/>
  </joint>
  <joint name="rightPinkyPitch3" type="fixed">
    <origin rpy="0.0 0.0 0.0" xyz="0.0 -0.0229 0.0"/>
    <axis xyz="0 0 1"/>
    <parent link="rightPinkyPitch2Link"/>
    <child link="rightPinkyPitch3Link"/>
    <limit effort="10" lower="0.0" upper="1.92" velocity="1"/>
    <dynamics damping="0.5" friction="0.5"/>
  </joint>

  <link name="leftShoulderPitchLink">
    <inertial>
      <mass value="2.65"/>
      <origin rpy="0 0 0" xyz="-0.012 0.251 0.000000"/>
      <inertia ixx="0.013718167" ixy="0.0" ixz="0.0" iyy="0.010502833" iyz="0.0" izz="0.014806433"/>
    </inertial>
    <visual>
      <geometry>
        <mesh filename="meshes2/arms/aj1_left.dae"/>
      </geometry>
      <origin rpy="0.0 0.0 0.0" xyz="0.0 0.0 0.0"/>
    </visual>
    <collision>
      <geometry>
        <mesh filename="meshes2/arms/aj1_left.dae"/>
      </geometry>
      <origin rpy="0 0 0" xyz="0 0 0"/>
    </collision>
  </link>


  <link name="leftShoulderRollLink">
    <inertial>
      <mass value="3.97"/>
      <origin rpy="0 0 0" xyz="-0.008513 0.02068 -0.001088"/>
      <inertia ixx="0.014598842" ixy="-0.00066764" ixz="-3.629e-05" iyy="0.006452136" iyz="-8.283e-05" izz="0.016848319"/>
    </inertial>
    <visual>
      <geometry>
        <mesh filename="meshes2/arms/aj2_left.dae"/>
      </geometry>
      <origin rpy="0.0 0.0 0.0" xyz="0.0 0.0 0.0"/>
    </visual>
    <collision>
      <geometry>
        <mesh filename="meshes2/arms/aj2_left.dae"/>
      </geometry>
      <origin rpy="0 0 0" xyz="0 0 0"/>
    </collision>
  </link>
  <link name="leftShoulderYawLink">
    <inertial>
      <mass value="3.085"/>
      <origin rpy="0 0 0" xyz="-0.004304 0.209832 0.007295"/>
      <inertia ixx="0.039355177" ixy="-0.007827077" ixz="-0.000753947" iyy="0.004905765" iyz="0.002723873" izz="0.041879481"/>
    </inertial>
    <visual>
      <geometry>
        <mesh filename="meshes2/arms/aj3_left.dae"/>
      </geometry>
      <origin rpy="0.0 0.0 0.0" xyz="0.0 0.0 0.0"/>
    </visual>
    <collision>
      <geometry>
        <mesh filename="meshes2/arms/aj3_left.dae"/>
      </geometry>
      <origin rpy="0 0 0" xyz="0 0 0"/>
    </collision>
  </link>
  <link name="leftElbowPitchLink">
    <inertial>
      <mass value="1.83"/>
      <origin rpy="0 0 0" xyz="-0.020344 0.014722 0.0223"/>
      <inertia ixx="0.003314516" ixy="0.000535099" ixz="0.000728077" iyy="0.003505669" iyz="-0.000423865" izz="0.003011283"/>
    </inertial>
    <visual>
      <geometry>
        <mesh filename="meshes2/arms/aj4_left.dae"/>
      </geometry>
      <origin rpy="0.0 0.0 0.0" xyz="0.0 0.0 0.0"/>
    </visual>
    <collision>
      <geometry>
        <mesh filename="meshes2/arms/aj4_left.dae"/>
      </geometry>
      <origin rpy="0 0 0" xyz="0 0 0"/>
    </collision>
  </link>








  <link name="leftForearmLink">
    <inertial>
      <mass value="2.476"/>
      <origin rpy="0 0 0" xyz="0.015000 0.13 0.019564"/>
      <inertia ixx="0.01175543" ixy="0.001300853" ixz="-0.000727141" iyy="0.005071567" iyz="0.001695416" izz="0.011365657"/>
    </inertial>
    <visual>
      <geometry>
        <mesh filename="meshes2/arms/aj5_left.dae"/>
      </geometry>
      <origin rpy="0.0 0.0 0.0" xyz="0.0 0.0 0.0"/>
    </visual>
    <collision>
      <geometry>
        <mesh filename="meshes2/arms/aj5_left.dae"/>
      </geometry>
      <origin rpy="0 0 0" xyz="0 0 0"/>
    </collision>
  </link>
  <link name="leftWristRollLink">
    <inertial>
      <mass value="0.14"/>
      <origin rpy="0 0 0" xyz="0 0.0 0"/>
      <inertia ixx="3.0251e-05" ixy="1.25e-07" ixz="3.6e-08" iyy="3.772e-05" iyz="0.0" izz="9.395e-06"/>
    </inertial>
    <visual>
      <geometry>
        <mesh filename="meshes2/arms/aj6_left.dae"/>
      </geometry>
      <origin rpy="0.0 0.0 0.0" xyz="0.0 0.0 0.0"/>
    </visual>
    <collision>
      <geometry>
        <mesh filename="meshes2/arms/aj6_left.dae"/>
      </geometry>
      <origin rpy="0 0 0" xyz="0 0 0"/>
    </collision>
  </link>
  <link name="leftPalm">
    <inertial>
      <mass value="0.712"/>
      <origin rpy="0 0 0" xyz="0.002954 0.052034 -0.000236"/>
      <inertia ixx="0.000943493" ixy="3.4393e-05" ixz="3.8828e-05" iyy="0.000711024" iyz="-2.3429e-05" izz="0.000610199"/>
    </inertial>
    <visual>
      <geometry>
        <mesh filename="meshes2/arms/palm_left.dae"/>
      </geometry>
      <origin rpy="0.0 0.0 0.0" xyz="0.0 0.0 0.0"/>
    </visual>
    <collision>
      <geometry>
        <mesh filename="meshes2/arms/palm_left.dae"/>
      </geometry>
      <origin rpy="0 0 0" xyz="0 0 0"/>
    </collision>
  </link>

  <link name="leftThumbRollLink">
    <inertial>
      <mass value="0.017"/>
      <origin rpy="0 0 0" xyz="0 0.0 0.01"/>
      <inertia ixx="2.7778767e-06" ixy="5.6718533e-09" ixz="9.5523207e-08" iyy="3.5462642e-06" iyz="-3.663718e-08" izz="1.3553297e-06"/>
    </inertial>
    <visual>
      <geometry>
        <mesh filename="meshes2/fingers/thumbj1_left.dae"/>
      </geometry>
      <origin rpy="0.0 0.0 0.0" xyz="0.0 0.0 0.0"/>
    </visual>
    <collision>
      <geometry>
        <mesh filename="meshes2/fingers/thumbj1_left.dae"/>
      </geometry>
      <origin rpy="0 0 0" xyz="0 0 0"/>
    </collision>
  </link>
  <link name="leftThumbPitch1Link">
    <inertial>
      <mass value="0.02"/>
      <origin rpy="0 0 0" xyz="0.0 0.005 0.02"/>
      <inertia ixx="4.239e-06" ixy="0.0" ixz="0.0" iyy="4.582e-06" iyz="-0.0" izz="1.47e-06"/>
    </inertial>
    <visual>
      <geometry>
        <mesh filename="meshes2/fingers/thumbj2_left.dae"/>
      </geometry>
      <origin rpy="0.0 0.0 0.0" xyz="0.0 0.0 0.0"/>
    </visual>
    <collision>
      <geometry>
        <mesh filename="meshes2/fingers/thumbj2_left.dae"/>
      </geometry>
      <origin rpy="0 0 0" xyz="0 0 0"/>
    </collision>
  </link>
  <link name="leftThumbPitch2Link">
    <inertial>
      <mass value="0.013"/>
      <origin rpy="0 0 0" xyz="0 0.004 0.017"/>
      <inertia ixx="1.266e-06" ixy="0.0" ixz="0.0" iyy="1.503e-06" iyz="0.0" izz="6.99e-07"/>
    </inertial>
    <visual>
      <geometry>
        <mesh filename="meshes2/fingers/thumbj3_left.dae"/>
      </geometry>
      <origin rpy="0.0 0.0 0.0" xyz="0.0 0.0 0.0"/>
    </visual>
    <collision>
      <geometry>
        <mesh filename="meshes2/fingers/thumbj3_left.dae"/>
      </geometry>
      <origin rpy="0 0 0" xyz="0 0 0"/>
    </collision>
  </link>
  <link name="leftThumbPitch3Link">
    <inertial>
      <mass value="0.006"/>
      <origin rpy="0 0 0" xyz="0 0.004 0.01"/>
      <inertia ixx="3.22e-07" ixy="0.0" ixz="0.0" iyy="4.06e-07" iyz="0.0" izz="2.1e-07"/>
    </inertial>
    <visual>
      <geometry>
        <mesh filename="meshes2/fingers/thumbj4_left.dae"/>
      </geometry>
      <origin rpy="0.0 0.0 0.0" xyz="0.0 0.0 0.0"/>
    </visual>
    <collision>
      <geometry>
        <mesh filename="meshes2/fingers/thumbj4_left.dae"/>
      </geometry>
      <origin rpy="0 0 0" xyz="0 0 0"/>
    </collision>
  </link>
  <gazebo reference="leftThumbPitch3Link">
    <kp>1e5</kp>
    <kd>1</kd>
    <maxVel>0.1</maxVel>
    <minDepth>0.0015</minDepth>
  </gazebo>
  <joint name="leftThumbRoll" type="fixed">
    <origin rpy="-0.3491 0.0 0.0" xyz="0.0049 0.0351 0.0228"/>
    <axis xyz="0 1 0"/>
    <parent link="leftPalm"/>
    <child link="leftThumbRollLink"/>
    <limit effort="10" lower="0.0" upper="2.356" velocity="1"/>
    <dynamics damping="0.5" friction="0.5"/>
  </joint>
  <gazebo reference="leftThumbRoll">
    <provideFeedback>1</provideFeedback>
    <implicitSpringDamper>1</implicitSpringDamper>
  </gazebo>
  <joint name="leftThumbPitch1" type="fixed">
    <origin rpy="0.3491 0.0 0.0" xyz="0.0 0.0 0.0229"/>
    <axis xyz="1 0 0"/>
    <parent link="leftThumbRollLink"/>
    <child link="leftThumbPitch1Link"/>
    <limit effort="10" lower="-1.658" upper="-0.0" velocity="1"/>
    <dynamics damping="0.5" friction="0.5"/>
  </joint>
  <gazebo reference="leftThumbPitch1">
    <provideFeedback>1</provideFeedback>
    <implicitSpringDamper>1</implicitSpringDamper>
  </gazebo>
  <joint name="leftThumbPitch2" type="fixed">
    <origin rpy="0.0 0.0 0.0" xyz="0.0 0.0066 0.0375"/>
    <axis xyz="1 0 0"/>
    <parent link="leftThumbPitch1Link"/>
    <child link="leftThumbPitch2Link"/>
    <limit effort="10" lower="-1.92" upper="-0.0" velocity="1"/>
    <dynamics damping="0.5" friction="0.5"/>
  </joint>
  <gazebo reference="leftThumbPitch2">
    <provideFeedback>1</provideFeedback>
    <implicitSpringDamper>1</implicitSpringDamper>
  </gazebo>
  <joint name="leftThumbPitch3" type="fixed">
    <origin rpy="0.0 0.0 0.0" xyz="0.0 0.0049 0.0275"/>
    <axis xyz="1 0 0"/>
    <parent link="leftThumbPitch2Link"/>
    <child link="leftThumbPitch3Link"/>
    <limit effort="10" lower="-1.57" upper="-0.0" velocity="1"/>
    <dynamics damping="0.5" friction="0.5"/>
  </joint>
  <gazebo reference="leftThumbPitch3">
    <provideFeedback>1</provideFeedback>
    <implicitSpringDamper>1</implicitSpringDamper>
  </gazebo>
  <link name="leftIndexFingerPitch1Link">
    <inertial>
      <mass value="0.02"/>
      <origin rpy="0 0 0" xyz="0 0.02 0"/>
      <inertia ixx="4.232e-06" ixy="6e-08" ixz="8e-09" iyy="1.215e-06" iyz="-7e-09" izz="3.892e-06"/>
    </inertial>
    <visual>
      <geometry>
        <mesh filename="meshes2/fingers/indexj1_left.dae"/>
      </geometry>
      <origin rpy="0.0 0.0 0.0" xyz="0.0 0.0 0.0"/>
    </visual>
    <collision>
      <geometry>
        <mesh filename="meshes2/fingers/indexj1_left.dae"/>
      </geometry>
      <origin rpy="0 0 0" xyz="0 0 0"/>
    </collision>
  </link>
  <gazebo reference="leftIndexFingerPitch1Link">
    <kp>1e5</kp>
    <kd>1</kd>
    <maxVel>0.1</maxVel>
    <minDepth>0.0015</minDepth>
  </gazebo>
  <link name="leftIndexFingerPitch2Link">
    <inertial>
      <mass value="0.018"/>
      <origin rpy="0 0 0" xyz="0 0.013 0"/>
      <inertia ixx="1.562e-06" ixy="1.7e-08" ixz="1.3e-08" iyy="7.22e-07" iyz="3.1e-08" izz="1.255e-06"/>
    </inertial>
    <visual>
      <geometry>
        <mesh filename="meshes2/fingers/indexj2_left.dae"/>
      </geometry>
      <origin rpy="0.0 0.0 0.0" xyz="0.0 0.0 0.0"/>
    </visual>
    <collision>
      <geometry>
        <mesh filename="meshes2/fingers/indexj2_left.dae"/>
      </geometry>
      <origin rpy="0 0 0" xyz="0 0 0"/>
    </collision>
  </link>
  <gazebo reference="leftIndexFingerPitch2Link">
    <kp>1e5</kp>
    <kd>1</kd>
    <maxVel>0.1</maxVel>
    <minDepth>0.0015</minDepth>
  </gazebo>
  <link name="leftIndexFingerPitch3Link">
    <inertial>
      <mass value="0.01"/>
      <origin rpy="0 0 0" xyz="0 0.01 0"/>
      <inertia ixx="6.02e-07" ixy="2.4e-08" ixz="-0.0" iyy="2.09e-07" iyz="1.7e-08" izz="5.02e-07"/>
    </inertial>
    <visual>
      <geometry>
        <mesh filename="meshes2/fingers/indexj3_left.dae"/>
      </geometry>
      <origin rpy="0.0 0.0 0.0" xyz="0.0 0.0 0.0"/>
    </visual>
    <collision>
      <geometry>
        <mesh filename="meshes2/fingers/indexj3_left.dae"/>
      </geometry>
      <origin rpy="0 0 0" xyz="0 0 0"/>
    </collision>
  </link>
  <gazebo reference="leftIndexFingerPitch3Link">
    <kp>1e5</kp>
    <kd>1</kd>
    <maxVel>0.1</maxVel>
    <minDepth>0.0015</minDepth>
  </gazebo>
  <joint name="leftIndexFingerPitch1" type="fixed">
    <origin rpy="0.1745 0.0 0.0" xyz="0.0022 0.0976 0.0235"/>
    <axis xyz="0 0 1"/>
    <parent link="leftPalm"/>
    <child link="leftIndexFingerPitch1Link"/>
    <limit effort="10" lower="-1.57" upper="-0.0" velocity="1"/>
    <dynamics damping="0.5" friction="0.5"/>
  </joint>
  <gazebo reference="leftIndexFingerPitch1">
    <provideFeedback>1</provideFeedback>
    <implicitSpringDamper>1</implicitSpringDamper>
  </gazebo>
  <joint name="leftIndexFingerPitch2" type="fixed">
    <origin rpy="0.0 0.0 0.0" xyz="0.0 0.0381 0.0"/>
    <axis xyz="0 0 1"/>
    <parent link="leftIndexFingerPitch1Link"/>
    <child link="leftIndexFingerPitch2Link"/>
    <limit effort="10" lower="-1.658" upper="-0.0" velocity="1"/>
    <dynamics damping="0.5" friction="0.5"/>
  </joint>
  <gazebo reference="leftIndexFingerPitch2">
    <provideFeedback>1</provideFeedback>
    <implicitSpringDamper>1</implicitSpringDamper>
  </gazebo>
  <joint name="leftIndexFingerPitch3" type="fixed">
    <origin rpy="0.0 0.0 0.0" xyz="0.0 0.0229 0"/>
    <axis xyz="0 0 1"/>
    <parent link="leftIndexFingerPitch2Link"/>
    <child link="leftIndexFingerPitch3Link"/>
    <limit effort="10" lower="-1.92" upper="-0.0" velocity="1"/>
    <dynamics damping="0.5" friction="0.5"/>
  </joint>
  <gazebo reference="leftIndexFingerPitch3">
    <provideFeedback>1</provideFeedback>
    <implicitSpringDamper>1</implicitSpringDamper>
  </gazebo>
  <link name="leftMiddleFingerPitch1Link">
    <inertial>
      <mass value="0.02"/>
      <origin rpy="0 0 0" xyz="0 0.02 0"/>
      <inertia ixx="5.148e-06" ixy="4.2e-08" ixz="1.1e-08" iyy="1.322e-06" iyz="-4e-09" izz="4.592e-06"/>
    </inertial>
    <visual>
      <geometry>
        <mesh filename="meshes2/fingers/middlej1_left.dae"/>
      </geometry>
      <origin rpy="0.0 0.0 0.0" xyz="0.0 0.0 0.0"/>
    </visual>
    <collision>
      <geometry>
        <mesh filename="meshes2/fingers/middlej1_left.dae"/>
      </geometry>
      <origin rpy="0 0 0" xyz="0 0 0"/>
    </collision>
  </link>
  <gazebo reference="leftMiddleFingerPitch1Link">
    <kp>1e5</kp>
    <kd>1</kd>
    <maxVel>0.1</maxVel>
    <minDepth>0.0015</minDepth>
  </gazebo>
  <link name="leftMiddleFingerPitch2Link">
    <inertial>
      <mass value="0.011"/>
      <origin rpy="0 0 0" xyz="0 0.013 0"/>
      <inertia ixx="1.97e-06" ixy="-3.4e-08" ixz="1.1e-08" iyy="5.54e-07" iyz="-7.8e-08" izz="2.272e-06"/>
    </inertial>
    <visual>
      <geometry>
        <mesh filename="meshes2/fingers/middlej2_left.dae"/>
      </geometry>
      <origin rpy="0.0 0.0 0.0" xyz="0.0 0.0 0.0"/>
    </visual>
    <collision>
      <geometry>
        <mesh filename="meshes2/fingers/middlej2_left.dae"/>
      </geometry>
      <origin rpy="0 0 0" xyz="0 0 0"/>
    </collision>
  </link>
  <gazebo reference="leftMiddleFingerPitch2Link">
    <kp>1e5</kp>
    <kd>1</kd>
    <maxVel>0.1</maxVel>
    <minDepth>0.0015</minDepth>
  </gazebo>
  <link name="leftMiddleFingerPitch3Link">
    <inertial>
      <mass value="0.006"/>
      <origin rpy="0 0 0" xyz="0 0.01 0"/>
      <inertia ixx="3.96e-07" ixy="9e-09" ixz="1e-09" iyy="1.6e-07" iyz="1.6e-08" izz="3.03e-07"/>
    </inertial>
    <visual>
      <geometry>
        <mesh filename="meshes2/fingers/middlej3_left.dae"/>
      </geometry>
      <origin rpy="0.0 0.0 0.0" xyz="0.0 0.0 0.0"/>
    </visual>
    <collision>
      <geometry>
        <mesh filename="meshes2/fingers/middlej3_left.dae"/>
      </geometry>
      <origin rpy="0 0 0" xyz="0 0 0"/>
    </collision>
  </link>
  <gazebo reference="leftMiddleFingerPitch3Link">
    <kp>1e5</kp>
    <kd>1</kd>
    <maxVel>0.1</maxVel>
    <minDepth>0.0015</minDepth>
  </gazebo>
  <joint name="leftMiddleFingerPitch1" type="fixed">
    <origin rpy="-0.1222 0.0 0.0" xyz="0.0022 0.097 -0.0119"/>
    <axis xyz="0 0 1"/>
    <parent link="leftPalm"/>
    <child link="leftMiddleFingerPitch1Link"/>
    <limit effort="10" lower="-1.658" upper="-0.0" velocity="1"/>
    <dynamics damping="0.5" friction="0.5"/>
  </joint>
  <gazebo reference="leftMiddleFingerPitch1">
    <provideFeedback>1</provideFeedback>
    <implicitSpringDamper>1</implicitSpringDamper>
  </gazebo>
  <joint name="leftMiddleFingerPitch2" type="fixed">
    <origin rpy="0.0 0.0 0.0" xyz="0.0 0.0381 0.0"/>
    <axis xyz="0 0 1"/>
    <parent link="leftMiddleFingerPitch1Link"/>
    <child link="leftMiddleFingerPitch2Link"/>
    <limit effort="10" lower="-1.92" upper="-0.0" velocity="1"/>
    <dynamics damping="0.5" friction="0.5"/>
  </joint>
  <gazebo reference="leftMiddleFingerPitch2">
    <provideFeedback>1</provideFeedback>
    <implicitSpringDamper>1</implicitSpringDamper>
  </gazebo>
  <joint name="leftMiddleFingerPitch3" type="fixed">
    <origin rpy="0.0 0.0 0.0" xyz="0.0 0.0229 0.0"/>
    <axis xyz="0 0 1"/>
    <parent link="leftMiddleFingerPitch2Link"/>
    <child link="leftMiddleFingerPitch3Link"/>
    <limit effort="10" lower="-1.57" upper="-0.0" velocity="1"/>
    <dynamics damping="0.5" friction="0.5"/>
  </joint>
  <gazebo reference="leftMiddleFingerPitch3">
    <provideFeedback>1</provideFeedback>
    <implicitSpringDamper>1</implicitSpringDamper>
  </gazebo>
  <link name="leftPinkyPitch1Link">
    <inertial>
      <mass value="0.02"/>
      <origin rpy="0 0 0" xyz="0 0.02 0"/>
      <inertia ixx="5.148e-06" ixy="4.2e-08" ixz="1.1e-08" iyy="1.322e-06" iyz="-4e-09" izz="4.592e-06"/>
    </inertial>
    <visual>
      <geometry>
        <mesh filename="meshes2/fingers/pinkyj1_left.dae"/>
      </geometry>
      <origin rpy="0.0 0.0 0.0" xyz="0.0 0.0 0.0"/>
    </visual>
    <collision>
      <geometry>
        <mesh filename="meshes2/fingers/pinkyj1_left.dae"/>
      </geometry>
      <origin rpy="0 0 0" xyz="0 0 0"/>
    </collision>
  </link>
  <gazebo reference="leftPinkyPitch1Link">
    <kp>1e5</kp>
    <kd>1</kd>
    <maxVel>0.1</maxVel>
    <minDepth>0.0015</minDepth>
  </gazebo>
  <link name="leftPinkyPitch2Link">
    <inertial>
      <mass value="0.011"/>
      <origin rpy="0 0 0" xyz="0 0.013 0"/>
      <inertia ixx="1.97e-06" ixy="-3.4e-08" ixz="1.1e-08" iyy="5.54e-07" iyz="-7.8e-08" izz="2.272e-06"/>
    </inertial>
    <visual>
      <geometry>
        <mesh filename="meshes2/fingers/pinkyj2_left.dae"/>
      </geometry>
      <origin rpy="0.0 0.0 0.0" xyz="0.0 0.0 0.0"/>
    </visual>
    <collision>
      <geometry>
        <mesh filename="meshes2/fingers/pinkyj2_left.dae"/>
      </geometry>
      <origin rpy="0 0 0" xyz="0 0 0"/>
    </collision>
  </link>
  <gazebo reference="leftPinkyPitch2Link">
    <kp>1e5</kp>
    <kd>1</kd>
    <maxVel>0.1</maxVel>
    <minDepth>0.0015</minDepth>
  </gazebo>
  <link name="leftPinkyPitch3Link">
    <inertial>
      <mass value="0.006"/>
      <origin rpy="0 0 0" xyz="0 0.01 0"/>
      <inertia ixx="3.96e-07" ixy="9e-09" ixz="1e-09" iyy="1.6e-07" iyz="1.6e-08" izz="3.03e-07"/>
    </inertial>
    <visual>
      <geometry>
        <mesh filename="meshes2/fingers/pinkyj3_left.dae"/>
      </geometry>
      <origin rpy="0.0 0.0 0.0" xyz="0.0 0.0 0.0"/>
    </visual>
    <collision>
      <geometry>
        <mesh filename="meshes2/fingers/pinkyj3_left.dae"/>
      </geometry>
      <origin rpy="0 0 0" xyz="0 0 0"/>
    </collision>
  </link>
  <gazebo reference="leftPinkyPitch3Link">
    <kp>1e5</kp>
    <kd>1</kd>
    <maxVel>0.1</maxVel>
    <minDepth>0.0015</minDepth>
  </gazebo>
  <joint name="leftPinkyPitch1" type="fixed">
    <origin rpy="-0.1222 0.0 0.0" xyz="0.0022 0.0838 -0.041"/>
    <axis xyz="0 0 1"/>
    <parent link="leftPalm"/>
    <child link="leftPinkyPitch1Link"/>
    <limit effort="10" lower="-1.57" upper="-0.0" velocity="1"/>
    <dynamics damping="0.5" friction="0.5"/>
  </joint>
  <gazebo reference="leftPinkyPitch1">
    <provideFeedback>1</provideFeedback>
    <implicitSpringDamper>1</implicitSpringDamper>
  </gazebo>
  <joint name="leftPinkyPitch2" type="fixed">
    <origin rpy="0.0 0.0 0.0" xyz="0.0 0.0381 0.0"/>
    <axis xyz="0 0 1"/>
    <parent link="leftPinkyPitch1Link"/>
    <child link="leftPinkyPitch2Link"/>
    <limit effort="10" lower="-1.658" upper="-0.0" velocity="1"/>
    <dynamics damping="0.5" friction="0.5"/>
  </joint>
  <gazebo reference="leftPinkyPitch2">
    <provideFeedback>1</provideFeedback>
    <implicitSpringDamper>1</implicitSpringDamper>
  </gazebo>
  <joint name="leftPinkyPitch3" type="fixed">
    <origin rpy="0.0 0.0 0.0" xyz="0.0 0.0229 0.0"/>
    <axis xyz="0 0 1"/>
    <parent link="leftPinkyPitch2Link"/>
    <child link="leftPinkyPitch3Link"/>
    <limit effort="10" lower="-1.92" upper="-0.0" velocity="1"/>
    <dynamics damping="0.5" friction="0.5"/>
  </joint>
  <gazebo reference="leftPinkyPitch3">
    <provideFeedback>1</provideFeedback>
    <implicitSpringDamper>1</implicitSpringDamper>
  </gazebo>
  <link name="rightHipYawLink">
    <inertial>
      <mass value="2.39"/>
      <origin rpy="0 0 0" xyz="0.02176 0.00131 0.03867"/>
      <inertia ixx="0.017260978" ixy="0.0" ixz="0.0" iyy="0.014866198" iyz="0.0" izz="0.011238178"/>
    </inertial>
    <visual>
      <geometry>
        <mesh filename="meshes2/legs/lj1_right.dae"/>
      </geometry>
      <origin rpy="0.0 0.0 0.0" xyz="0.0 0.0 0.0"/>
    </visual>
    <collision>
      <geometry>
        <mesh filename="meshes2/legs/lj1_right.dae"/>
      </geometry>
      <origin rpy="0 0 0" xyz="0 0 0"/>
    </collision>
  </link>
  <link name="rightHipRollLink">
    <inertial>
      <mass value="3.665"/>
      <origin rpy="0 0 0" xyz="0.012959 -0.00755 -0.015950"/>
      <inertia ixx="0.005978962" ixy="0.000234823" ixz="0.000553962" iyy="0.009372646" iyz="-0.000778956" izz="0.008193117"/>
    </inertial>
  </link>
  <link name="rightHipPitchLink">
    <inertial>
      <mass value="10.2"/>
      <origin rpy="0 0 0" xyz="0.016691 -0.091397 -0.207875"/>
      <inertia ixx="0.24083413" ixy="-3.5915e-05" ixz="0.003699383" iyy="0.25689705" iyz="0.001333005" izz="0.023276352"/>
    </inertial>
    <visual>
      <geometry>
        <mesh filename="meshes2/legs/lj3_right.dae"/>
      </geometry>
      <origin rpy="0.0 0.0 0.0" xyz="0.0 0.0 0.0"/>
    </visual>
    <collision>
      <geometry>
        <mesh filename="meshes2/legs/lj3_right.dae"/>
      </geometry>
      <origin rpy="0 0 0" xyz="0 0 0"/>
    </collision>
  </link>
  <link name="rightKneePitchLink">
    <inertial>
      <mass value="6.2"/>
      <origin rpy="0 0 0" xyz="-0.022183  0.001703  -0.189418"/>
      <inertia ixx="0.086935683" ixy="9.929e-05" ixz="0.000573207" iyy="0.091584066" iyz="0.000313745" izz="0.014017272"/>
    </inertial>
    <visual>
      <geometry>
        <mesh filename="meshes2/legs/lj4_right.dae"/>
      </geometry>
      <origin rpy="0.0 0.0 0.0" xyz="0.0 0.0 0.0"/>
    </visual>
    <collision>
      <geometry>
        <mesh filename="meshes2/legs/lj4_right.dae"/>
      </geometry>
      <origin rpy="0 0 0" xyz="0 0 0"/>
    </collision>
  </link>
  <link name="rightAnklePitchLink">
    <inertial>
      <mass value="0.03"/>
      <origin rpy="0 0 0" xyz="0.0 0.0 0.0"/>
      <inertia ixx="4.377e-06" ixy="0.0" ixz="0.0" iyy="4.322e-06" iyz="0.0" izz="7.015e-06"/>
    </inertial>
    <visual>
      <geometry>
        <mesh filename="meshes2/legs/lj5.dae"/>
      </geometry>
      <origin rpy="0.0 0.0 0.0" xyz="0.0 0.0 0.0"/>
    </visual>
    <collision>
      <geometry>
        <mesh filename="meshes2/legs/lj5.dae"/>
      </geometry>
      <origin rpy="0 0 0" xyz="0 0 0"/>
    </collision>
  </link>
  <link name="rightFoot">
    <inertial>
      <mass value="2.27"/>
      <origin rpy="0 0 0" xyz="0.037702  0.005161  -0.047634"/>
      <inertia ixx="0.00623936" ixy="0.000217174" ixz="0.001340587" iyy="0.017786991" iyz="-0.000187749" izz="0.020774433"/>
    </inertial>
    <visual>
      <geometry>
        <mesh filename="meshes2/legs/foot.dae"/>
      </geometry>
      <origin rpy="0 0 0" xyz="0 0 0"/>
    </visual>
    <collision>
      <geometry>
        <box size="0.27 0.16 0.064"/>
      </geometry>
      <origin rpy="0.0 0.0 0.0" xyz="0.045 0.0 -0.056"/>
    </collision>
  </link>

  <joint name="rightHipYaw" type="fixed">
    <origin rpy="0.0 0.0 0.0" xyz="0.0 -0.1016 -0.1853"/>
    <axis xyz="0 0 1"/>
    <parent link="pelvis"/>
    <child link="rightHipYawLink"/>
    <limit effort="190" lower="-1.1" upper="0.4141" velocity="5.89"/>

    <dynamics damping="0.1" friction="0.0"/>
  </joint>
  <joint name="rightHipRoll" type="fixed">
    <origin rpy="0.0 0.0 0.0" xyz="0.0 0.0 0.0"/>
    <axis xyz="1 0 0"/>
    <parent link="rightHipYawLink"/>
    <child link="rightHipRollLink"/>
    <limit effort="350" lower="-0.5515" upper="0.467" velocity="7"/>

    <dynamics damping="0.1" friction="0.0"/>
  </joint>
  <joint name="rightHipPitch" type="fixed">
    <origin rpy="0.0 0.0 0.0" xyz="0.0 0.0 -0.0609"/>
    <axis xyz="0 1 0"/>
    <parent link="rightHipRollLink"/>
    <child link="rightHipPitchLink"/>
    <limit effort="350" lower="-2.42" upper="1.619" velocity="6.11"/>

    <dynamics damping="0.1" friction="0.0"/>
  </joint>
  <joint name="rightKneePitch" type="fixed">
    <origin rpy="0.0 0.0 0.0" xyz="0.000112225 -0.0361046 -0.430959"/>
    <axis xyz="0 1 0"/>
    <parent link="rightHipPitchLink"/>
    <child link="rightKneePitchLink"/>
    <limit effort="350" lower="-0.083" upper="2.057" velocity="6.11"/>

    <dynamics damping="0.1" friction="0.0"/>
  </joint>
  <joint name="rightAnklePitch" type="fixed">
    <origin rpy="0.0 0.0 0.0" xyz="-0.0102381 0.0 -0.40627"/>
    <axis xyz="0 1 0"/>
    <parent link="rightKneePitchLink"/>
    <child link="rightAnklePitchLink"/>
    <limit effort="205" lower="-0.93" upper="0.65" velocity="11"/>

    <dynamics damping="0.1" friction="0.0"/>
  </joint>
  <joint name="rightAnkleRoll" type="fixed">
    <origin rpy="0.0 0.0 0.0" xyz="0.0 0.0 0.0"/>
    <axis xyz="1 0 0"/>
    <parent link="rightAnklePitchLink"/>
    <child link="rightFoot"/>
    <limit effort="205" lower="-0.4" upper="0.4" velocity="11"/>

    <dynamics damping="0.3" friction="0.0"/>
  </joint>
  <gazebo reference="rightAnkleRoll">
    <provideFeedback>1</provideFeedback>
    <implicitSpringDamper>1</implicitSpringDamper>
  </gazebo>
  <link name="leftHipYawLink">
    <inertial>
      <mass value="2.39"/>
      <origin rpy="0 0 0" xyz="0.02176 -0.00131 0.03867"/>
      <inertia ixx="0.017260978" ixy="0.0" ixz="0.0" iyy="0.014866198" iyz="0.0" izz="0.011238178"/>
    </inertial>
    <visual>
      <geometry>
        <mesh filename="meshes2/legs/lj1_left.dae"/>
      </geometry>
      <origin rpy="0.0 0.0 0.0" xyz="0.0 0.0 0.0"/>
    </visual>
    <collision>
      <geometry>
        <mesh filename="meshes2/legs/lj1_left.dae"/>
      </geometry>
      <origin rpy="0 0 0" xyz="0 0 0"/>
    </collision>
  </link>
  <link name="leftHipRollLink">
    <inertial>
      <mass value="3.665"/>
      <origin rpy="0 0 0" xyz="0.012959 0.00755 -0.015950"/>
      <inertia ixx="0.005978962" ixy="-0.000234823" ixz="0.000553962" iyy="0.009372646" iyz="0.000778956" izz="0.008193117"/>
    </inertial>
  </link>
  <link name="leftHipPitchLink">
    <inertial>
      <mass value="10.2"/>
      <origin rpy="0 0 0" xyz="0.016691 0.091397 -0.207875"/>
      <inertia ixx="0.24083413" ixy="3.5915e-05" ixz="0.003699383" iyy="0.25689705" iyz="-0.001333005" izz="0.023276352"/>
    </inertial>
    <visual>
      <geometry>
        <mesh filename="meshes2/legs/lj3_left.dae"/>
      </geometry>
      <origin rpy="0.0 0.0 0.0" xyz="0.0 0.0 0.0"/>
    </visual>
    <collision>
      <geometry>
        <mesh filename="meshes2/legs/lj3_left.dae"/>
      </geometry>
      <origin rpy="0 0 0" xyz="0 0 0"/>
    </collision>
  </link>
  <link name="leftKneePitchLink">
    <inertial>
      <mass value="6.2"/>
      <origin rpy="0 0 0" xyz="-0.022183  0.001703  -0.189418"/>
      <inertia ixx="0.086935683" ixy="9.929e-05" ixz="0.000573207" iyy="0.091584066" iyz="0.000313745" izz="0.014017272"/>
    </inertial>
    <visual>
      <geometry>
        <mesh filename="meshes2/legs/lj4_left.dae"/>
      </geometry>
      <origin rpy="0.0 0.0 0.0" xyz="0.0 0.0 0.0"/>
    </visual>
    <collision>
      <geometry>
        <mesh filename="meshes2/legs/lj4_left.dae"/>
      </geometry>
      <origin rpy="0 0 0" xyz="0 0 0"/>
    </collision>
  </link>
  <link name="leftAnklePitchLink">
    <inertial>
      <mass value="0.03"/>
      <origin rpy="0 0 0" xyz="0.0 0.0 0.0"/>
      <inertia ixx="4.377e-06" ixy="0.0" ixz="0.0" iyy="4.322e-06" iyz="0.0" izz="7.015e-06"/>
    </inertial>
    <visual>
      <geometry>
        <mesh filename="meshes2/legs/lj5.dae"/>
      </geometry>
      <origin rpy="0.0 0.0 0.0" xyz="0.0 0.0 0.0"/>
    </visual>
    <collision>
      <geometry>
        <mesh filename="meshes2/legs/lj5.dae"/>
      </geometry>
      <origin rpy="0 0 0" xyz="0 0 0"/>
    </collision>
  </link>
  <link name="leftFoot">
    <inertial>
      <mass value="2.27"/>
      <origin rpy="0 0 0" xyz="0.037702  0.005161  -0.047634"/>
      <inertia ixx="0.00623936" ixy="0.000217174" ixz="0.001340587" iyy="0.017786991" iyz="-0.000187749" izz="0.020774433"/>
    </inertial>
    <visual>
      <geometry>
        <mesh filename="meshes2/legs/foot.dae"/>
      </geometry>
      <origin rpy="0 0 0" xyz="0 0 0"/>
    </visual>
    <collision>
      <geometry>
        <box size="0.27 0.16 0.064"/>
      </geometry>
      <origin rpy="0.0 0.0 0.0" xyz="0.045 0.0 -0.056"/>
    </collision>
  </link>
  <!-- foot contact parameters copied from atlas_description in drcsim -->
  <gazebo reference="leftFoot">
    <!-- kp and kd for rubber -->
    <kp>1000000.0</kp>
    <kd>100.0</kd>
    <mu1>1.5</mu1>
    <mu2>1.5</mu2>
    <fdir1>1 0 0</fdir1>
    <maxVel>1.0</maxVel>
    <minDepth>0.00</minDepth>
  </gazebo>
  <joint name="leftHipYaw" type="fixed">
    <origin rpy="0.0 0.0 0.0" xyz="0.0 0.1016 -0.1853"/>
    <axis xyz="0 0 1"/>
    <parent link="pelvis"/>
    <child link="leftHipYawLink"/>
    <limit effort="190" lower="-0.4141" upper="1.1" velocity="5.89"/>

    <dynamics damping="0.1" friction="0.0"/>
  </joint>
  <gazebo reference="leftHipYaw">
    <provideFeedback>1</provideFeedback>
    <implicitSpringDamper>1</implicitSpringDamper>
  </gazebo>
  <joint name="leftHipRoll" type="fixed">
    <origin rpy="0.0 0.0 0.0" xyz="0.0 0.0 0.0"/>
    <axis xyz="1 0 0"/>
    <parent link="leftHipYawLink"/>
    <child link="leftHipRollLink"/>
    <limit effort="350" lower="-0.467" upper="0.5515" velocity="7"/>

    <dynamics damping="0.1" friction="0.0"/>
  </joint>
  <gazebo reference="leftHipRoll">
    <provideFeedback>1</provideFeedback>
    <implicitSpringDamper>1</implicitSpringDamper>
  </gazebo>
  <joint name="leftHipPitch" type="fixed">
    <origin rpy="0.0 0.0 0.0" xyz="0.0 0.0 -0.0609"/>
    <axis xyz="0 1 0"/>
    <parent link="leftHipRollLink"/>
    <child link="leftHipPitchLink"/>
    <limit effort="350" lower="-2.42" upper="1.619" velocity="6.11"/>

    <dynamics damping="0.1" friction="0.0"/>
  </joint>
  <gazebo reference="leftHipPitch">
    <provideFeedback>1</provideFeedback>
    <implicitSpringDamper>1</implicitSpringDamper>
  </gazebo>
  <joint name="leftKneePitch" type="fixed">
    <origin rpy="0.0 0.0 0.0" xyz="0.000112225 0.0361046 -0.430959"/>
    <axis xyz="0 1 0"/>
    <parent link="leftHipPitchLink"/>
    <child link="leftKneePitchLink"/>
    <limit effort="350" lower="-0.083" upper="2.057" velocity="6.11"/>

    <dynamics damping="0.1" friction="0.0"/>
  </joint>
  <gazebo reference="leftKneePitch">
    <provideFeedback>1</provideFeedback>
    <implicitSpringDamper>1</implicitSpringDamper>
  </gazebo>
  <joint name="leftAnklePitch" type="fixed">
    <origin rpy="0.0 0.0 0.0" xyz="-0.0102381 0.0 -0.40627"/>
    <axis xyz="0 1 0"/>
    <parent link="leftKneePitchLink"/>
    <child link="leftAnklePitchLink"/>
    <limit effort="205" lower="-0.93" upper="0.65" velocity="11"/>

    <dynamics damping="0.1" friction="0.0"/>
  </joint>
  <gazebo reference="leftAnklePitch">
    <provideFeedback>1</provideFeedback>
    <implicitSpringDamper>1</implicitSpringDamper>
  </gazebo>
  <joint name="leftAnkleRoll" type="fixed">
    <origin rpy="0.0 0.0 0.0" xyz="0.0 0.0 0.0"/>
    <axis xyz="1 0 0"/>
    <parent link="leftAnklePitchLink"/>
    <child link="leftFoot"/>
    <limit effort="205" lower="-0.4" upper="0.4" velocity="11"/>

    <dynamics damping="0.3" friction="0.0"/>
  </joint>
  <gazebo reference="leftAnkleRoll">
    <provideFeedback>1</provideFeedback>
    <implicitSpringDamper>1</implicitSpringDamper>
  </gazebo>
  <link name="leftTorsoImu_Frame">
    <!-- Virtual Link -->
    <inertial>
      <mass value="1e-07"/>
      <origin rpy="0 0 0" xyz="0 0 0"/>
      <inertia ixx="3.33333333333e-22" ixy="0.0" ixz="0.0" iyy="3.33333333333e-22" iyz="0.0" izz="5e-22"/>
    </inertial>
  </link>
  <joint name="leftTorsoImu_Offset" type="fixed">
    <origin rpy="-1.5707 0.0 0.0" xyz="-0.0627634 0.134239 0.3630676"/>
    <axis xyz="0 0 1"/>
    <parent link="torso"/>
    <child link="leftTorsoImu_Frame"/>
  </joint>
  <gazebo reference="leftTorsoImu_Offset">
    <implicitSpringDamper>1</implicitSpringDamper>
  </gazebo>
  <gazebo>
    <plugin filename="libgazebo_ros_imu.so" name="imu_plugin_ros">
      <alwaysOn>true</alwaysOn>
      <bodyName>leftTorsoImu_Frame</bodyName>
      <topicName>leftTorsoImu/imu</topicName>
      <serviceName>leftTorsoImu/imu_service</serviceName>
      <gaussianNoise>0.0</gaussianNoise>
      <updateRate>1000.0</updateRate>
    </plugin>
  </gazebo>
  <gazebo reference="leftTorsoImu_Frame">
    <sensor name="leftTorsoImu" type="imu">
      <imuTransform>-0.0627634 0.134239 0.3630676 -1.5707 0.0 0.0</imuTransform>
      <always_on>true</always_on>
      <pose>0 0 0 0 0 0 </pose>
      <node name="/sensors/leftTorsoIMU"/>
      <api name="imu_3dm_gx4_15_sensor::Imu3DmGx415Sensor"/>
      <port name="/dev/serial/by-id/usb-Lord_Microstrain_Lord_Inertial_Sensor_0000__6233.47090-if00"/>
      <imu>
        <noise>
          <type>gaussian</type>
          <rate>
            <mean>0</mean>
            <stddev>0.0002</stddev>
            <bias_mean>7.5e-06</bias_mean>
            <bias_stddev>8e-07</bias_stddev>
          </rate>
          <accel>
            <mean>0</mean>
            <stddev>0.017</stddev>
            <bias_mean>0.1</bias_mean>
            <bias_stddev>0.001</bias_stddev>
          </accel>
        </noise>
      </imu>
    </sensor>
  </gazebo>
  <link name="rightHazardCamera_Frame">
    <!-- Virtual Link -->
    <inertial>
      <mass value="1e-07"/>
      <origin rpy="0 0 0" xyz="0 0 0"/>
      <inertia ixx="3.33333333333e-22" ixy="0.0" ixz="0.0" iyy="3.33333333333e-22" iyz="0.0" izz="5e-22"/>
    </inertial>
  </link>
  <gazebo reference="rightHazardCamera_Frame">
    <sensor name="rightHazardCamera" type="camera">
      <camera>
        <image>
          <width>1280</width>
          <height>1024</height>
          <format>R8G8B8</format>
        </image>
        <horizontal_fov>1.378</horizontal_fov>
        <clip>
          <near>0.1</near>
          <far>100</far>
        </clip>
      </camera>
      <update_rate>60</update_rate>
    </sensor>
  </gazebo>
  <joint name="rightHazardCamera_Offset" type="fixed">
    <origin rpy="1.57 0.0 1.57" xyz="0.0345 -0.0406 0.1135"/>
    <axis xyz="0 0 1"/>
    <parent link="torso"/>
    <child link="rightHazardCamera_Frame"/>
  </joint>
  <gazebo reference="rightHazardCamera_Offset">
    <implicitSpringDamper>1</implicitSpringDamper>
  </gazebo>
  <link name="leftHazardCamera_Frame">
    <!-- Virtual Link -->
    <inertial>
      <mass value="1e-07"/>
      <origin rpy="0 0 0" xyz="0 0 0"/>
      <inertia ixx="3.33333333333e-22" ixy="0.0" ixz="0.0" iyy="3.33333333333e-22" iyz="0.0" izz="5e-22"/>
    </inertial>
  </link>
  <gazebo reference="leftHazardCamera_Frame">
    <sensor name="leftHazardCamera" type="camera">
      <camera>
        <image>
          <width>1280</width>
          <height>1024</height>
          <format>R8G8B8</format>
        </image>
        <horizontal_fov>1.378</horizontal_fov>
        <clip>
          <near>0.1</near>
          <far>100</far>
        </clip>
      </camera>
      <update_rate>60</update_rate>
    </sensor>
  </gazebo>
  <joint name="leftHazardCamera_Offset" type="fixed">
    <origin rpy="1.57 0.0 1.57" xyz="0.0345 0.0406 0.1135"/>
    <axis xyz="0 0 1"/>
    <parent link="torso"/>
    <child link="leftHazardCamera_Frame"/>
  </joint>
  <gazebo reference="leftHazardCamera_Offset">
    <implicitSpringDamper>1</implicitSpringDamper>
  </gazebo>
  <link name="leftCOP_Frame">
    <inertial>
      <mass value="0.1"/>
      <origin rpy="0 0 0" xyz="0 0 0"/>
      <inertia ixx="8.33333333333e-05" ixy="0.0" ixz="0.0" iyy="8.33333333333e-05" iyz="0.0" izz="0.000125"/>
    </inertial>
  </link>
  <joint name="leftCOP_Offset" type="fixed">
    <origin rpy="0.0 0.0 0.0" xyz="0.0189 0.0 -0.0783"/>
    <axis xyz="0 0 1"/>
    <parent link="leftFoot"/>
    <child link="leftCOP_Frame"/>
  </joint>
  <gazebo reference="leftCOP_Offset">
    <implicitSpringDamper>1</implicitSpringDamper>
  </gazebo>
  <link name="leftFootSixAxis_Frame">
    <!-- Virtual Link -->
    <inertial>
      <mass value="1e-07"/>
      <origin rpy="0 0 0" xyz="0 0 0"/>
      <inertia ixx="3.33333333333e-22" ixy="0.0" ixz="0.0" iyy="3.33333333333e-22" iyz="0.0" izz="5e-22"/>
    </inertial>
  </link>
  <joint name="leftFootSixAxis_Offset" type="fixed">
    <origin rpy="3.14 0.0 0.0" xyz="0.0215646 0.0 -0.051054"/>
    <axis xyz="0 0 1"/>
    <parent link="leftFoot"/>
    <child link="leftFootSixAxis_Frame"/>
  </joint>
  <gazebo reference="leftFootSixAxis_Offset">
    <implicitSpringDamper>1</implicitSpringDamper>
  </gazebo>
  <gazebo reference="leftAnkleRoll">
    <sensor name="leftFootSixAxis" type="force_torque">
      <pose>0.0215646 0.0 -0.051054 3.14 0.0 0.0</pose>
      <sensor_number id="FT17218"/>
      <node id="/left_leg/ankle/left_actuator"/>
      <api name="ati_sensor_interface::ATISensorInterface"/>
      <always_on>true</always_on>
      <update_rate>500.0</update_rate>
      <force_torque>
        <frame>sensor</frame>
        <measure_direction>parent_to_child</measure_direction>
      </force_torque>
    </sensor>
  </gazebo>
  <link name="rightCOP_Frame">
    <inertial>
      <mass value="0.1"/>
      <origin rpy="0 0 0" xyz="0 0 0"/>
      <inertia ixx="8.33333333333e-05" ixy="0.0" ixz="0.0" iyy="8.33333333333e-05" iyz="0.0" izz="0.000125"/>
    </inertial>
  </link>
  <joint name="rightCOP_Offset" type="fixed">
    <origin rpy="0.0 0.0 0.0" xyz="0.0189 0.0 -0.0783"/>
    <axis xyz="0 0 1"/>
    <parent link="rightFoot"/>
    <child link="rightCOP_Frame"/>
  </joint>
  <gazebo reference="rightCOP_Offset">
    <implicitSpringDamper>1</implicitSpringDamper>
  </gazebo>
  <link name="rightFootSixAxis_Frame">
    <!-- Virtual Link -->
    <inertial>
      <mass value="1e-07"/>
      <origin rpy="0 0 0" xyz="0 0 0"/>
      <inertia ixx="3.33333333333e-22" ixy="0.0" ixz="0.0" iyy="3.33333333333e-22" iyz="0.0" izz="5e-22"/>
    </inertial>
  </link>
  <joint name="rightFootSixAxis_Offset" type="fixed">
    <origin rpy="3.14 0.0 0.0" xyz="0.0215646 0.0 -0.051054"/>
    <axis xyz="0 0 1"/>
    <parent link="rightFoot"/>
    <child link="rightFootSixAxis_Frame"/>
  </joint>
  <gazebo reference="rightFootSixAxis_Offset">
    <implicitSpringDamper>1</implicitSpringDamper>
  </gazebo>
  <gazebo reference="rightAnkleRoll">
    <sensor name="rightFootSixAxis" type="force_torque">
      <pose>0.0215646 0.0 -0.051054 3.14 0.0 0.0</pose>
      <sensor_number id="FT14018"/>
      <node id="/right_leg/ankle/left_actuator"/>
      <api name="ati_sensor_interface::ATISensorInterface"/>
      <always_on>true</always_on>
      <update_rate>500.0</update_rate>
      <force_torque>
        <frame>sensor</frame>
        <measure_direction>parent_to_child</measure_direction>
      </force_torque>
    </sensor>
  </gazebo>
  <link name="multisense_root_link">
    <!-- Virtual Link -->
    <inertial>
      <mass value="1e-07"/>
      <origin rpy="0 0 0" xyz="0 0 0"/>
      <inertia ixx="3.33333333333e-22" ixy="0.0" ixz="0.0" iyy="3.33333333333e-22" iyz="0.0" izz="5e-22"/>
    </inertial>
  </link>
  <joint name="multisense_head_root_joint" type="fixed">
    <origin rpy="-3.14159 0.130899694 0.0" xyz="0.183585961 0.0 0.075353826"/>
    <axis xyz="0 0 1"/>
    <parent link="upperNeckPitchLink"/>
    <child link="multisense_root_link"/>
  </joint>
  <gazebo reference="multisense_head_root_joint">
    <implicitSpringDamper>1</implicitSpringDamper>
  </gazebo>
  <link name="pelvisRearImu_Frame">
    <!-- Virtual Link -->
    <inertial>
      <mass value="1e-07"/>
      <origin rpy="0 0 0" xyz="0 0 0"/>
      <inertia ixx="3.33333333333e-22" ixy="0.0" ixz="0.0" iyy="3.33333333333e-22" iyz="0.0" izz="5e-22"/>
    </inertial>
  </link>
  <joint name="pelvisRearImu_Offset" type="fixed">
    <origin rpy="-3.14159 0.476467 -3.14159" xyz="-0.075844901 0.0 -0.111056426"/>
    <axis xyz="0 0 1"/>
    <parent link="pelvis"/>
    <child link="pelvisRearImu_Frame"/>
  </joint>

  <!-- The y-z coordinates were flipped for some reason. We add this tag so that klampt accounts for this flip. See https://github.com/krishauser/Klampt/blob/master/Cpp/docs/Tutorials/Import-and-calibrate-urdf.md -->
  <klampt flip_yz="1"/>
  
</robot>
